{"metadata":{"kernelspec":{"language":"python","display_name":"Python 3","name":"python3"},"language_info":{"name":"python","version":"3.10.12","mimetype":"text/x-python","codemirror_mode":{"name":"ipython","version":3},"pygments_lexer":"ipython3","nbconvert_exporter":"python","file_extension":".py"},"kaggle":{"accelerator":"none","dataSources":[{"sourceId":225031124,"sourceType":"kernelVersion"}],"dockerImageVersionId":30918,"isInternetEnabled":false,"language":"python","sourceType":"notebook","isGpuEnabled":false}},"nbformat_minor":4,"nbformat":4,"cells":[{"cell_type":"code","source":"Q1. What is an Exception in python? Write the difference between Exceptions and Syntax \nerrors.\nAns1. Exception is an error in the python program that disrupts the flow of program. Exception\noccur during the execution of the program in the cases where we try to divide any number by zero\nor trying to open a file in read mode which is not created already. If exception occurs \nin any line of the code then the instructions after that line are not executed. In order\nto avoid this scenario we perform exception handling.\n\nHowever the systax errros occur when we do not follow the syntax rule of the programming \nlanguage. \n    \nExmaples of Exception and syntax error:","metadata":{"trusted":true},"outputs":[],"execution_count":null},{"cell_type":"code","source":"#exception error\na=10\nprint(a/0)","metadata":{"trusted":true,"execution":{"iopub.status.busy":"2025-02-28T22:10:12.690862Z","iopub.execute_input":"2025-02-28T22:10:12.691251Z","iopub.status.idle":"2025-02-28T22:10:12.783770Z","shell.execute_reply.started":"2025-02-28T22:10:12.691219Z","shell.execute_reply":"2025-02-28T22:10:12.782312Z"}},"outputs":[{"traceback":["\u001b[0;31m---------------------------------------------------------------------------\u001b[0m","\u001b[0;31mZeroDivisionError\u001b[0m                         Traceback (most recent call last)","\u001b[0;32m<ipython-input-2-e59b72106679>\u001b[0m in \u001b[0;36m<cell line: 3>\u001b[0;34m()\u001b[0m\n\u001b[1;32m      1\u001b[0m \u001b[0;31m#exception error\u001b[0m\u001b[0;34m\u001b[0m\u001b[0;34m\u001b[0m\u001b[0m\n\u001b[1;32m      2\u001b[0m \u001b[0ma\u001b[0m\u001b[0;34m=\u001b[0m\u001b[0;36m10\u001b[0m\u001b[0;34m\u001b[0m\u001b[0;34m\u001b[0m\u001b[0m\n\u001b[0;32m----> 3\u001b[0;31m \u001b[0mprint\u001b[0m\u001b[0;34m(\u001b[0m\u001b[0ma\u001b[0m\u001b[0;34m/\u001b[0m\u001b[0;36m0\u001b[0m\u001b[0;34m)\u001b[0m\u001b[0;34m\u001b[0m\u001b[0;34m\u001b[0m\u001b[0m\n\u001b[0m","\u001b[0;31mZeroDivisionError\u001b[0m: division by zero"],"ename":"ZeroDivisionError","evalue":"division by zero","output_type":"error"}],"execution_count":2},{"cell_type":"code","source":"#Syntax error:\nif x==5                    #missing colon\n    print(\"values of x is \",x)","metadata":{"trusted":true,"execution":{"iopub.status.busy":"2025-02-28T22:12:31.501280Z","iopub.execute_input":"2025-02-28T22:12:31.501665Z","iopub.status.idle":"2025-02-28T22:12:31.508716Z","shell.execute_reply.started":"2025-02-28T22:12:31.501634Z","shell.execute_reply":"2025-02-28T22:12:31.507137Z"}},"outputs":[{"traceback":["\u001b[0;36m  File \u001b[0;32m\"<ipython-input-3-7114e5f57bf3>\"\u001b[0;36m, line \u001b[0;32m2\u001b[0m\n\u001b[0;31m    if x==5                    #missing colon\u001b[0m\n\u001b[0m                               ^\u001b[0m\n\u001b[0;31mSyntaxError\u001b[0m\u001b[0;31m:\u001b[0m expected ':'\n"],"ename":"SyntaxError","evalue":"expected ':' (<ipython-input-3-7114e5f57bf3>, line 2)","output_type":"error"}],"execution_count":3},{"cell_type":"code","source":"Q2. What happens when an exception is not handled? Explain with an example.\nAns2. If in any program an exception occurs and it is not handled then our rest of the \nprogram is not executed after the exception. That simply means our whole program crashes \nafter exception occurs in any one instruction of the program.\n\nExample-->","metadata":{"trusted":true},"outputs":[],"execution_count":null},{"cell_type":"code","source":"a=10\nb=a/0\nprint(\"this statement is not going to be printed\")\nprint(\"Because divide by zero exception in second line is not handled.\")","metadata":{"trusted":true,"execution":{"iopub.status.busy":"2025-02-28T22:15:10.716923Z","iopub.execute_input":"2025-02-28T22:15:10.717322Z","iopub.status.idle":"2025-02-28T22:15:10.729532Z","shell.execute_reply.started":"2025-02-28T22:15:10.717292Z","shell.execute_reply":"2025-02-28T22:15:10.728065Z"}},"outputs":[{"traceback":["\u001b[0;31m---------------------------------------------------------------------------\u001b[0m","\u001b[0;31mZeroDivisionError\u001b[0m                         Traceback (most recent call last)","\u001b[0;32m<ipython-input-4-f2f1d8a38810>\u001b[0m in \u001b[0;36m<cell line: 2>\u001b[0;34m()\u001b[0m\n\u001b[1;32m      1\u001b[0m \u001b[0ma\u001b[0m\u001b[0;34m=\u001b[0m\u001b[0;36m10\u001b[0m\u001b[0;34m\u001b[0m\u001b[0;34m\u001b[0m\u001b[0m\n\u001b[0;32m----> 2\u001b[0;31m \u001b[0mb\u001b[0m\u001b[0;34m=\u001b[0m\u001b[0ma\u001b[0m\u001b[0;34m/\u001b[0m\u001b[0;36m0\u001b[0m\u001b[0;34m\u001b[0m\u001b[0;34m\u001b[0m\u001b[0m\n\u001b[0m\u001b[1;32m      3\u001b[0m \u001b[0mprint\u001b[0m\u001b[0;34m(\u001b[0m\u001b[0;34m\"this statement is not going to be printed\"\u001b[0m\u001b[0;34m)\u001b[0m\u001b[0;34m\u001b[0m\u001b[0;34m\u001b[0m\u001b[0m\n\u001b[1;32m      4\u001b[0m \u001b[0mprint\u001b[0m\u001b[0;34m(\u001b[0m\u001b[0;34m\"Because divide by zero exception in second line is not handled.\"\u001b[0m\u001b[0;34m)\u001b[0m\u001b[0;34m\u001b[0m\u001b[0;34m\u001b[0m\u001b[0m\n","\u001b[0;31mZeroDivisionError\u001b[0m: division by zero"],"ename":"ZeroDivisionError","evalue":"division by zero","output_type":"error"}],"execution_count":4},{"cell_type":"code","source":"Q3. Which Python statements are used to catch and handle exceptions? Explain with an \nexample.\n\nAns3. To handle exception in python, we use try-except block. The advantage of using this\nblock is that even if the exception occurs in that case our whole program does not terminate\nabruptly. The rest of the program is executed normally.\n","metadata":{"trusted":true},"outputs":[],"execution_count":null},{"cell_type":"code","source":"try:\n    a=10\n    b=a/0\nexcept Exception as e:\n    print(e)\nprint(\"This statement is going to be printed since exception is handled successfully\")\nprint(\"exception handling avoid the abrupt termination of the program\")","metadata":{"trusted":true,"execution":{"iopub.status.busy":"2025-02-28T22:20:10.031918Z","iopub.execute_input":"2025-02-28T22:20:10.032342Z","iopub.status.idle":"2025-02-28T22:20:10.040231Z","shell.execute_reply.started":"2025-02-28T22:20:10.032312Z","shell.execute_reply":"2025-02-28T22:20:10.038863Z"}},"outputs":[{"name":"stdout","text":"division by zero\nThis statement is going to be printed since exception is handled successfully\nexception handling avoid the abrupt termination of the program\n","output_type":"stream"}],"execution_count":5},{"cell_type":"code","source":"Q4. Explain with an example:\n\ntry and else\nfinally\nraise\n\nAns4. When we are handling exception then along with try-except we can also use else block.\nThis else block is executed when no error/exception occured in our try block, that means\nour full try block is executed successfully. In the case if exception occurs in the try block\nthen the control will go to the except block as usual but then else block will not be \nexecuted.\n\nfinally--> finally block is used with try-except block in the case where we want certain\nstatements to be executed in any case like closing the open file or disconnecting from the \ndatabase.\n\nraise--> raise keyword is in the cases where we create custom exception. Like in any case\nif our program does not behave in a desired manner, then we create manual exception for  \nthat program. We will understand how it is used in the program.","metadata":{"trusted":true},"outputs":[],"execution_count":null},{"cell_type":"code","source":"# else block will be executed in this program\ntry:\n    file=open(\"test.txt\",'w')\n    file.write(\"Write in the file text\")\nexcept Exceptions as e:\n    print(e)\nelse:\n    print(\"This block will be executed only if try block is executed without any exception\")","metadata":{"trusted":true,"execution":{"iopub.status.busy":"2025-02-28T22:29:48.821864Z","iopub.execute_input":"2025-02-28T22:29:48.822285Z","iopub.status.idle":"2025-02-28T22:29:48.829122Z","shell.execute_reply.started":"2025-02-28T22:29:48.822253Z","shell.execute_reply":"2025-02-28T22:29:48.827873Z"}},"outputs":[{"name":"stdout","text":"This block will be executed only if try block is executed without any exception\n","output_type":"stream"}],"execution_count":6},{"cell_type":"code","source":"# else block will not be executed here because of exception in try block.\ntry:\n    a=10\n    b=a/0\nexcept Exception as e:\n    print(e)\nelse:\n    print(\"This block will not be executed since exception ocuured in the try block\")","metadata":{"trusted":true,"execution":{"iopub.status.busy":"2025-02-28T22:32:31.885601Z","iopub.execute_input":"2025-02-28T22:32:31.886077Z","iopub.status.idle":"2025-02-28T22:32:31.891459Z","shell.execute_reply.started":"2025-02-28T22:32:31.886042Z","shell.execute_reply":"2025-02-28T22:32:31.890109Z"}},"outputs":[{"name":"stdout","text":"division by zero\n","output_type":"stream"}],"execution_count":7},{"cell_type":"code","source":"# Example for raise\nclass customexception(Exception):\n    def __init__(self,msg):\n        self.msg=msg\n\n    def excmethod():\n        raise customexception(\"This method raise an exception\")\n\ntry:\n    customexception.excmethod()\nexcept customexception as e:\n    print(e)","metadata":{"trusted":true,"execution":{"iopub.status.busy":"2025-02-28T22:42:54.708998Z","iopub.execute_input":"2025-02-28T22:42:54.709379Z","iopub.status.idle":"2025-02-28T22:42:54.715694Z","shell.execute_reply.started":"2025-02-28T22:42:54.709349Z","shell.execute_reply":"2025-02-28T22:42:54.714509Z"}},"outputs":[{"name":"stdout","text":"This method raise an exception\n","output_type":"stream"}],"execution_count":9},{"cell_type":"code","source":"Q5. What are Custom Exceptions in python? Why do we need Custom Exceptions? Explain with an example.\nAns5. In Python, custom exceptions are user-defined exceptions that we can create by subclassing \nthe built-in Exception class. By creating custom exceptions, \nwe can handle specific error cases more effectively and provide more meaningful error \nmessages, tailored to the context of the application.","metadata":{"trusted":true},"outputs":[],"execution_count":null},{"cell_type":"code","source":"class numexception(Exception):\n    def __init__(self,msg):\n        self.msg=msg\n    def num_check(num):\n        if num>=1000:\n            raise numexception(\"The number should be less than 1000\")\n        else:\n            print(\"valid number\")\n\ntry:\n    num=int(input(\"enter any number less than 1000\"))\n    numexception.num_check(num)\nexcept numexception as e:\n    print(e)    ","metadata":{"trusted":true,"execution":{"iopub.status.busy":"2025-02-28T22:58:47.126428Z","iopub.execute_input":"2025-02-28T22:58:47.128054Z","iopub.status.idle":"2025-02-28T22:58:52.216360Z","shell.execute_reply.started":"2025-02-28T22:58:47.127977Z","shell.execute_reply":"2025-02-28T22:58:52.215103Z"}},"outputs":[{"output_type":"stream","name":"stdin","text":"enter any number less than 1000 999\n"},{"name":"stdout","text":"valid number\n","output_type":"stream"}],"execution_count":12},{"cell_type":"code","source":"Q6. Create a custom exception class. Use this class to handle an exception.","metadata":{"trusted":true},"outputs":[],"execution_count":null},{"cell_type":"code","source":"class validateageexception(Exception):\n    def __init__(self,msg):\n        self.msg=msg\n    def validage(age):\n        if age<0:\n            raise validateageexception(\"age is negative\")\n        elif age>120:\n            raise validateageexception(\"age is very very high\")\n        else:\n            print(\"age is valid\")\n\ntry:\n    age=int(input(\"pleae enter your age\"))\n    validateageexception.validage(age)\nexcept validateageexception as e:\n    print(e)","metadata":{"trusted":true,"execution":{"iopub.status.busy":"2025-02-28T22:54:39.361367Z","iopub.execute_input":"2025-02-28T22:54:39.361763Z","iopub.status.idle":"2025-02-28T22:54:43.382716Z","shell.execute_reply.started":"2025-02-28T22:54:39.361708Z","shell.execute_reply":"2025-02-28T22:54:43.381424Z"}},"outputs":[{"output_type":"stream","name":"stdin","text":"pleae enter your age -90\n"},{"name":"stdout","text":"age is negative\n","output_type":"stream"}],"execution_count":11}]}